异常是会一层层往上传递的
如
def test1():
	print(num)
因为num未定义，执行到此处会出现异常，
而该段落所在的test1()方法没有try, except块，无法捕获异常，
则test1()会把异常抛给外层调用自己的代码，让其try, except处理，
如果没有，再往上抛出，
直到最外层传递给系统，由PYTHON解释器抛出，停止运行……